2021-09-15 11:43:08,979 ERROR: Exception on /download_csv [POST] [in C:\Users\chilker\Anaconda3\envs\attachment\lib\site-packages\flask\app.py:1891]
Traceback (most recent call last):
  File "C:\Users\chilker\Anaconda3\envs\attachment\lib\site-packages\flask\app.py", line 2447, in wsgi_app
    response = self.full_dispatch_request()
  File "C:\Users\chilker\Anaconda3\envs\attachment\lib\site-packages\flask\app.py", line 1952, in full_dispatch_request
    rv = self.handle_user_exception(e)
  File "C:\Users\chilker\Anaconda3\envs\attachment\lib\site-packages\flask\app.py", line 1821, in handle_user_exception
    reraise(exc_type, exc_value, tb)
  File "C:\Users\chilker\Anaconda3\envs\attachment\lib\site-packages\flask\_compat.py", line 39, in reraise
    raise value
  File "C:\Users\chilker\Anaconda3\envs\attachment\lib\site-packages\flask\app.py", line 1950, in full_dispatch_request
    rv = self.dispatch_request()
  File "C:\Users\chilker\Anaconda3\envs\attachment\lib\site-packages\flask\app.py", line 1936, in dispatch_request
    return self.view_functions[rule.endpoint](**req.view_args)
  File "C:\Users\chilker\Projects\RP_Trending\QCSTM_124\app\routes.py", line 107, in download_csv
    cw.write(csv_str)
AttributeError: '_csv.writer' object has no attribute 'write'
2021-09-15 11:45:04,796 INFO: Attachment startup [in C:\Users\chilker\Projects\RP_Trending\QCSTM_124\app\__init__.py:29]
2021-09-15 11:45:35,248 INFO: Attachment startup [in C:\Users\chilker\Projects\RP_Trending\QCSTM_124\app\__init__.py:29]
2021-09-15 11:50:23,001 INFO: Attachment startup [in C:\Users\chilker\Projects\RP_Trending\QCSTM_124\app\__init__.py:29]
2021-09-15 11:50:33,187 ERROR: Exception on /download_csv [POST] [in C:\Users\chilker\Anaconda3\envs\attachment\lib\site-packages\flask\app.py:1891]
Traceback (most recent call last):
  File "C:\Users\chilker\Anaconda3\envs\attachment\lib\site-packages\flask\app.py", line 2447, in wsgi_app
    response = self.full_dispatch_request()
  File "C:\Users\chilker\Anaconda3\envs\attachment\lib\site-packages\flask\app.py", line 1952, in full_dispatch_request
    rv = self.handle_user_exception(e)
  File "C:\Users\chilker\Anaconda3\envs\attachment\lib\site-packages\flask\app.py", line 1821, in handle_user_exception
    reraise(exc_type, exc_value, tb)
  File "C:\Users\chilker\Anaconda3\envs\attachment\lib\site-packages\flask\_compat.py", line 39, in reraise
    raise value
  File "C:\Users\chilker\Anaconda3\envs\attachment\lib\site-packages\flask\app.py", line 1950, in full_dispatch_request
    rv = self.dispatch_request()
  File "C:\Users\chilker\Anaconda3\envs\attachment\lib\site-packages\flask\app.py", line 1936, in dispatch_request
    return self.view_functions[rule.endpoint](**req.view_args)
  File "C:\Users\chilker\Projects\RP_Trending\QCSTM_124\app\routes.py", line 104, in download_csv
    csv_str += '"' + data + '"' + ","
UnboundLocalError: local variable 'csv_str' referenced before assignment
2021-09-15 11:50:50,580 INFO: Attachment startup [in C:\Users\chilker\Projects\RP_Trending\QCSTM_124\app\__init__.py:29]
2021-09-15 11:56:42,692 INFO: Attachment startup [in C:\Users\chilker\Projects\RP_Trending\QCSTM_124\app\__init__.py:29]
2021-09-15 11:57:40,603 INFO: Attachment startup [in C:\Users\chilker\Projects\RP_Trending\QCSTM_124\app\__init__.py:29]
2021-09-15 11:58:47,757 INFO: Attachment startup [in C:\Users\chilker\Projects\RP_Trending\QCSTM_124\app\__init__.py:29]
2021-09-15 11:59:41,807 INFO: Attachment startup [in C:\Users\chilker\Projects\RP_Trending\QCSTM_124\app\__init__.py:29]
2021-09-15 12:02:38,933 INFO: Attachment startup [in C:\Users\chilker\Projects\RP_Trending\QCSTM_124\app\__init__.py:29]
2021-09-15 12:04:08,198 INFO: Attachment startup [in C:\Users\chilker\Projects\RP_Trending\QCSTM_124\app\__init__.py:29]
2021-09-15 12:05:26,512 INFO: Attachment startup [in C:\Users\chilker\Projects\RP_Trending\QCSTM_124\app\__init__.py:29]
2021-09-15 12:09:25,693 INFO: Attachment startup [in C:\Users\chilker\Projects\RP_Trending\QCSTM_124\app\__init__.py:29]
2021-09-15 12:10:57,290 INFO: Attachment startup [in C:\Users\chilker\Projects\RP_Trending\QCSTM_124\app\__init__.py:29]
2021-09-15 12:12:11,590 INFO: Attachment startup [in C:\Users\chilker\Projects\RP_Trending\QCSTM_124\app\__init__.py:29]
2021-09-15 12:15:49,900 INFO: Attachment startup [in C:\Users\chilker\Projects\RP_Trending\QCSTM_124\app\__init__.py:29]
2021-09-15 12:29:23,977 INFO: Attachment startup [in C:\Users\chilker\Projects\RP_Trending\QCSTM_124\app\__init__.py:29]
2021-09-15 12:29:34,268 ERROR: Exception on /download_csv [POST] [in C:\Users\chilker\Anaconda3\envs\attachment\lib\site-packages\flask\app.py:1891]
Traceback (most recent call last):
  File "C:\Users\chilker\Anaconda3\envs\attachment\lib\site-packages\flask\app.py", line 2447, in wsgi_app
    response = self.full_dispatch_request()
  File "C:\Users\chilker\Anaconda3\envs\attachment\lib\site-packages\flask\app.py", line 1952, in full_dispatch_request
    rv = self.handle_user_exception(e)
  File "C:\Users\chilker\Anaconda3\envs\attachment\lib\site-packages\flask\app.py", line 1821, in handle_user_exception
    reraise(exc_type, exc_value, tb)
  File "C:\Users\chilker\Anaconda3\envs\attachment\lib\site-packages\flask\_compat.py", line 39, in reraise
    raise value
  File "C:\Users\chilker\Anaconda3\envs\attachment\lib\site-packages\flask\app.py", line 1950, in full_dispatch_request
    rv = self.dispatch_request()
  File "C:\Users\chilker\Anaconda3\envs\attachment\lib\site-packages\flask\app.py", line 1936, in dispatch_request
    return self.view_functions[rule.endpoint](**req.view_args)
  File "C:\Users\chilker\Projects\RP_Trending\QCSTM_124\app\routes.py", line 101, in download_csv
    for row in query:
NameError: name 'query' is not defined
2021-09-15 12:29:59,460 INFO: Attachment startup [in C:\Users\chilker\Projects\RP_Trending\QCSTM_124\app\__init__.py:29]
2021-09-15 12:30:09,673 ERROR: Exception on /download_csv [POST] [in C:\Users\chilker\Anaconda3\envs\attachment\lib\site-packages\flask\app.py:1891]
Traceback (most recent call last):
  File "C:\Users\chilker\Anaconda3\envs\attachment\lib\site-packages\flask\app.py", line 2447, in wsgi_app
    response = self.full_dispatch_request()
  File "C:\Users\chilker\Anaconda3\envs\attachment\lib\site-packages\flask\app.py", line 1952, in full_dispatch_request
    rv = self.handle_user_exception(e)
  File "C:\Users\chilker\Anaconda3\envs\attachment\lib\site-packages\flask\app.py", line 1821, in handle_user_exception
    reraise(exc_type, exc_value, tb)
  File "C:\Users\chilker\Anaconda3\envs\attachment\lib\site-packages\flask\_compat.py", line 39, in reraise
    raise value
  File "C:\Users\chilker\Anaconda3\envs\attachment\lib\site-packages\flask\app.py", line 1950, in full_dispatch_request
    rv = self.dispatch_request()
  File "C:\Users\chilker\Anaconda3\envs\attachment\lib\site-packages\flask\app.py", line 1936, in dispatch_request
    return self.view_functions[rule.endpoint](**req.view_args)
  File "C:\Users\chilker\Projects\RP_Trending\QCSTM_124\app\routes.py", line 116, in download_csv
    query_2 = [item for sublist in [x.errors.all() for row in query] for item in sublist]
NameError: name 'query' is not defined
2021-09-15 12:30:32,320 INFO: Attachment startup [in C:\Users\chilker\Projects\RP_Trending\QCSTM_124\app\__init__.py:29]
2021-09-15 12:30:40,506 ERROR: Exception on /download_csv [POST] [in C:\Users\chilker\Anaconda3\envs\attachment\lib\site-packages\flask\app.py:1891]
Traceback (most recent call last):
  File "C:\Users\chilker\Anaconda3\envs\attachment\lib\site-packages\flask\app.py", line 2447, in wsgi_app
    response = self.full_dispatch_request()
  File "C:\Users\chilker\Anaconda3\envs\attachment\lib\site-packages\flask\app.py", line 1952, in full_dispatch_request
    rv = self.handle_user_exception(e)
  File "C:\Users\chilker\Anaconda3\envs\attachment\lib\site-packages\flask\app.py", line 1821, in handle_user_exception
    reraise(exc_type, exc_value, tb)
  File "C:\Users\chilker\Anaconda3\envs\attachment\lib\site-packages\flask\_compat.py", line 39, in reraise
    raise value
  File "C:\Users\chilker\Anaconda3\envs\attachment\lib\site-packages\flask\app.py", line 1950, in full_dispatch_request
    rv = self.dispatch_request()
  File "C:\Users\chilker\Anaconda3\envs\attachment\lib\site-packages\flask\app.py", line 1936, in dispatch_request
    return self.view_functions[rule.endpoint](**req.view_args)
  File "C:\Users\chilker\Projects\RP_Trending\QCSTM_124\app\routes.py", line 116, in download_csv
    query_2 = [item for sublist in [x.errors.all() for row in query_1] for item in sublist]
  File "C:\Users\chilker\Projects\RP_Trending\QCSTM_124\app\routes.py", line 116, in <listcomp>
    query_2 = [item for sublist in [x.errors.all() for row in query_1] for item in sublist]
NameError: name 'x' is not defined
2021-09-15 12:31:06,224 INFO: Attachment startup [in C:\Users\chilker\Projects\RP_Trending\QCSTM_124\app\__init__.py:29]
