2021-09-13 11:48:41,506 ERROR: Exception on /enter_record [POST] [in C:\Users\chilker\Anaconda3\envs\attachment\lib\site-packages\flask\app.py:1891]
Traceback (most recent call last):
  File "C:\Users\chilker\Anaconda3\envs\attachment\lib\site-packages\flask\app.py", line 2447, in wsgi_app
    response = self.full_dispatch_request()
  File "C:\Users\chilker\Anaconda3\envs\attachment\lib\site-packages\flask\app.py", line 1952, in full_dispatch_request
    rv = self.handle_user_exception(e)
  File "C:\Users\chilker\Anaconda3\envs\attachment\lib\site-packages\flask\app.py", line 1821, in handle_user_exception
    reraise(exc_type, exc_value, tb)
  File "C:\Users\chilker\Anaconda3\envs\attachment\lib\site-packages\flask\_compat.py", line 39, in reraise
    raise value
  File "C:\Users\chilker\Anaconda3\envs\attachment\lib\site-packages\flask\app.py", line 1950, in full_dispatch_request
    rv = self.dispatch_request()
  File "C:\Users\chilker\Anaconda3\envs\attachment\lib\site-packages\flask\app.py", line 1936, in dispatch_request
    return self.view_functions[rule.endpoint](**req.view_args)
  File "C:\Users\chilker\Projects\RP_Trending\QCSTM_124\app\routes.py", line 54, in enter_record
    if len(lot_dat[0]) > 0 and lot_dat[1] != None:
TypeError: object of type 'datetime.date' has no len()
2021-09-13 11:48:51,905 INFO: Attachment startup [in C:\Users\chilker\Projects\RP_Trending\QCSTM_124\app\__init__.py:29]
2021-09-13 11:48:58,461 ERROR: Exception on /enter_record [POST] [in C:\Users\chilker\Anaconda3\envs\attachment\lib\site-packages\flask\app.py:1891]
Traceback (most recent call last):
  File "C:\Users\chilker\Anaconda3\envs\attachment\lib\site-packages\flask\app.py", line 2447, in wsgi_app
    response = self.full_dispatch_request()
  File "C:\Users\chilker\Anaconda3\envs\attachment\lib\site-packages\flask\app.py", line 1952, in full_dispatch_request
    rv = self.handle_user_exception(e)
  File "C:\Users\chilker\Anaconda3\envs\attachment\lib\site-packages\flask\app.py", line 1821, in handle_user_exception
    reraise(exc_type, exc_value, tb)
  File "C:\Users\chilker\Anaconda3\envs\attachment\lib\site-packages\flask\_compat.py", line 39, in reraise
    raise value
  File "C:\Users\chilker\Anaconda3\envs\attachment\lib\site-packages\flask\app.py", line 1950, in full_dispatch_request
    rv = self.dispatch_request()
  File "C:\Users\chilker\Anaconda3\envs\attachment\lib\site-packages\flask\app.py", line 1936, in dispatch_request
    return self.view_functions[rule.endpoint](**req.view_args)
  File "C:\Users\chilker\Projects\RP_Trending\QCSTM_124\app\routes.py", line 65, in enter_record
    for ind, id_type in enumerate([(ie1_id, ie1_type), (ie2_id, ie2_type), (ie3_id, ie3_type), (ie4_id, ie4_type), (ie5_id, ie5_type)]):
NameError: name 'ie1_id' is not defined
2021-09-13 11:50:54,930 ERROR: Exception on /enter_record [POST] [in C:\Users\chilker\Anaconda3\envs\attachment\lib\site-packages\flask\app.py:1891]
Traceback (most recent call last):
  File "C:\Users\chilker\Anaconda3\envs\attachment\lib\site-packages\flask\app.py", line 2447, in wsgi_app
    response = self.full_dispatch_request()
  File "C:\Users\chilker\Anaconda3\envs\attachment\lib\site-packages\flask\app.py", line 1952, in full_dispatch_request
    rv = self.handle_user_exception(e)
  File "C:\Users\chilker\Anaconda3\envs\attachment\lib\site-packages\flask\app.py", line 1821, in handle_user_exception
    reraise(exc_type, exc_value, tb)
  File "C:\Users\chilker\Anaconda3\envs\attachment\lib\site-packages\flask\_compat.py", line 39, in reraise
    raise value
  File "C:\Users\chilker\Anaconda3\envs\attachment\lib\site-packages\flask\app.py", line 1950, in full_dispatch_request
    rv = self.dispatch_request()
  File "C:\Users\chilker\Anaconda3\envs\attachment\lib\site-packages\flask\app.py", line 1936, in dispatch_request
    return self.view_functions[rule.endpoint](**req.view_args)
  File "C:\Users\chilker\Projects\RP_Trending\QCSTM_124\app\routes.py", line 65, in enter_record
    for ind, id_type in enumerate([(form.ie1_id.data, form.ie1_type.data), (form.ie2_id.data, form.ie2_type.data), (form.ie3_id.data, form.ie3_type.data), (form.ie4_id.data, form.ie4_type.data), (form.ie5_id.data, form.ie5_type.data)]):
NameError: name 'ie1_id' is not defined
2021-09-13 11:51:03,464 INFO: Attachment startup [in C:\Users\chilker\Projects\RP_Trending\QCSTM_124\app\__init__.py:29]
2021-09-13 11:51:07,368 ERROR: Exception on /enter_record [POST] [in C:\Users\chilker\Anaconda3\envs\attachment\lib\site-packages\flask\app.py:1891]
Traceback (most recent call last):
  File "C:\Users\chilker\Anaconda3\envs\attachment\lib\site-packages\flask\app.py", line 2447, in wsgi_app
    response = self.full_dispatch_request()
  File "C:\Users\chilker\Anaconda3\envs\attachment\lib\site-packages\flask\app.py", line 1952, in full_dispatch_request
    rv = self.handle_user_exception(e)
  File "C:\Users\chilker\Anaconda3\envs\attachment\lib\site-packages\flask\app.py", line 1821, in handle_user_exception
    reraise(exc_type, exc_value, tb)
  File "C:\Users\chilker\Anaconda3\envs\attachment\lib\site-packages\flask\_compat.py", line 39, in reraise
    raise value
  File "C:\Users\chilker\Anaconda3\envs\attachment\lib\site-packages\flask\app.py", line 1950, in full_dispatch_request
    rv = self.dispatch_request()
  File "C:\Users\chilker\Anaconda3\envs\attachment\lib\site-packages\flask\app.py", line 1936, in dispatch_request
    return self.view_functions[rule.endpoint](**req.view_args)
  File "C:\Users\chilker\Projects\RP_Trending\QCSTM_124\app\routes.py", line 66, in enter_record
    if is_ie == 'True' and len(id_type[0]) > 0 and len(id_type[1]) > 0:
NameError: name 'is_ie' is not defined
2021-09-13 11:51:32,161 ERROR: Exception on /enter_record [POST] [in C:\Users\chilker\Anaconda3\envs\attachment\lib\site-packages\flask\app.py:1891]
Traceback (most recent call last):
  File "C:\Users\chilker\Anaconda3\envs\attachment\lib\site-packages\flask\app.py", line 2447, in wsgi_app
    response = self.full_dispatch_request()
  File "C:\Users\chilker\Anaconda3\envs\attachment\lib\site-packages\flask\app.py", line 1952, in full_dispatch_request
    rv = self.handle_user_exception(e)
  File "C:\Users\chilker\Anaconda3\envs\attachment\lib\site-packages\flask\app.py", line 1821, in handle_user_exception
    reraise(exc_type, exc_value, tb)
  File "C:\Users\chilker\Anaconda3\envs\attachment\lib\site-packages\flask\_compat.py", line 39, in reraise
    raise value
  File "C:\Users\chilker\Anaconda3\envs\attachment\lib\site-packages\flask\app.py", line 1950, in full_dispatch_request
    rv = self.dispatch_request()
  File "C:\Users\chilker\Anaconda3\envs\attachment\lib\site-packages\flask\app.py", line 1936, in dispatch_request
    return self.view_functions[rule.endpoint](**req.view_args)
  File "C:\Users\chilker\Projects\RP_Trending\QCSTM_124\app\routes.py", line 66, in enter_record
    if form.is_ie.data == 'True' and len(id_type[0]) > 0 and len(id_type[1]) > 0:
NameError: name 'is_ie' is not defined
2021-09-13 11:51:36,499 INFO: Attachment startup [in C:\Users\chilker\Projects\RP_Trending\QCSTM_124\app\__init__.py:29]
2021-09-13 11:51:46,177 ERROR: Exception on /enter_record [POST] [in C:\Users\chilker\Anaconda3\envs\attachment\lib\site-packages\flask\app.py:1891]
Traceback (most recent call last):
  File "C:\Users\chilker\Anaconda3\envs\attachment\lib\site-packages\flask\app.py", line 2447, in wsgi_app
    response = self.full_dispatch_request()
  File "C:\Users\chilker\Anaconda3\envs\attachment\lib\site-packages\flask\app.py", line 1952, in full_dispatch_request
    rv = self.handle_user_exception(e)
  File "C:\Users\chilker\Anaconda3\envs\attachment\lib\site-packages\flask\app.py", line 1821, in handle_user_exception
    reraise(exc_type, exc_value, tb)
  File "C:\Users\chilker\Anaconda3\envs\attachment\lib\site-packages\flask\_compat.py", line 39, in reraise
    raise value
  File "C:\Users\chilker\Anaconda3\envs\attachment\lib\site-packages\flask\app.py", line 1950, in full_dispatch_request
    rv = self.dispatch_request()
  File "C:\Users\chilker\Anaconda3\envs\attachment\lib\site-packages\flask\app.py", line 1936, in dispatch_request
    return self.view_functions[rule.endpoint](**req.view_args)
  File "C:\Users\chilker\Projects\RP_Trending\QCSTM_124\app\routes.py", line 70, in enter_record
    vii_lot=lot_vii,
NameError: name 'lot_vii' is not defined
2021-09-13 11:52:14,749 INFO: Attachment startup [in C:\Users\chilker\Projects\RP_Trending\QCSTM_124\app\__init__.py:29]
2021-09-13 11:53:38,069 INFO: Attachment startup [in C:\Users\chilker\Projects\RP_Trending\QCSTM_124\app\__init__.py:29]
2021-09-13 11:54:19,021 INFO: Attachment startup [in C:\Users\chilker\Projects\RP_Trending\QCSTM_124\app\__init__.py:29]
2021-09-13 11:55:26,355 INFO: Attachment startup [in C:\Users\chilker\Projects\RP_Trending\QCSTM_124\app\__init__.py:29]
2021-09-13 11:55:43,376 INFO: Attachment startup [in C:\Users\chilker\Projects\RP_Trending\QCSTM_124\app\__init__.py:29]
2021-09-13 11:55:55,746 INFO: Attachment startup [in C:\Users\chilker\Projects\RP_Trending\QCSTM_124\app\__init__.py:29]
2021-09-13 11:56:22,567 INFO: Attachment startup [in C:\Users\chilker\Projects\RP_Trending\QCSTM_124\app\__init__.py:29]
2021-09-13 11:56:38,392 INFO: Attachment startup [in C:\Users\chilker\Projects\RP_Trending\QCSTM_124\app\__init__.py:29]
2021-09-13 12:00:20,590 INFO: Attachment startup [in C:\Users\chilker\Projects\RP_Trending\QCSTM_124\app\__init__.py:29]
2021-09-13 12:01:02,166 INFO: Attachment startup [in C:\Users\chilker\Projects\RP_Trending\QCSTM_124\app\__init__.py:29]
2021-09-13 12:01:30,078 INFO: Attachment startup [in C:\Users\chilker\Projects\RP_Trending\QCSTM_124\app\__init__.py:29]
2021-09-14 14:15:20,052 INFO: Attachment startup [in C:\Users\chilker\Projects\RP_Trending\QCSTM_124\app\__init__.py:29]
2021-09-14 14:16:41,913 INFO: Attachment startup [in C:\Users\chilker\Projects\RP_Trending\QCSTM_124\app\__init__.py:29]
