2021-09-15 13:01:28,732 ERROR: Exception on /download_csv [POST] [in C:\Users\chilker\Anaconda3\envs\attachment\lib\site-packages\flask\app.py:1891]
Traceback (most recent call last):
  File "C:\Users\chilker\Anaconda3\envs\attachment\lib\site-packages\flask\app.py", line 2447, in wsgi_app
    response = self.full_dispatch_request()
  File "C:\Users\chilker\Anaconda3\envs\attachment\lib\site-packages\flask\app.py", line 1952, in full_dispatch_request
    rv = self.handle_user_exception(e)
  File "C:\Users\chilker\Anaconda3\envs\attachment\lib\site-packages\flask\app.py", line 1821, in handle_user_exception
    reraise(exc_type, exc_value, tb)
  File "C:\Users\chilker\Anaconda3\envs\attachment\lib\site-packages\flask\_compat.py", line 39, in reraise
    raise value
  File "C:\Users\chilker\Anaconda3\envs\attachment\lib\site-packages\flask\app.py", line 1950, in full_dispatch_request
    rv = self.dispatch_request()
  File "C:\Users\chilker\Anaconda3\envs\attachment\lib\site-packages\flask\app.py", line 1936, in dispatch_request
    return self.view_functions[rule.endpoint](**req.view_args)
  File "C:\Users\chilker\Projects\RP_Trending\QCSTM_124\app\routes.py", line 113, in download_csv
    output_1.headers["Content-Disposition"] = "attachment; filename=QCSTM-124_run_table.csv"
AttributeError: 'str' object has no attribute 'headers'
2021-09-15 13:01:56,564 INFO: Attachment startup [in C:\Users\chilker\Projects\RP_Trending\QCSTM_124\app\__init__.py:29]
2021-09-15 13:02:05,919 ERROR: Exception on /download_csv [POST] [in C:\Users\chilker\Anaconda3\envs\attachment\lib\site-packages\flask\app.py:1891]
Traceback (most recent call last):
  File "C:\Users\chilker\Anaconda3\envs\attachment\lib\site-packages\flask\app.py", line 2447, in wsgi_app
    response = self.full_dispatch_request()
  File "C:\Users\chilker\Anaconda3\envs\attachment\lib\site-packages\flask\app.py", line 1952, in full_dispatch_request
    rv = self.handle_user_exception(e)
  File "C:\Users\chilker\Anaconda3\envs\attachment\lib\site-packages\flask\app.py", line 1821, in handle_user_exception
    reraise(exc_type, exc_value, tb)
  File "C:\Users\chilker\Anaconda3\envs\attachment\lib\site-packages\flask\_compat.py", line 39, in reraise
    raise value
  File "C:\Users\chilker\Anaconda3\envs\attachment\lib\site-packages\flask\app.py", line 1950, in full_dispatch_request
    rv = self.dispatch_request()
  File "C:\Users\chilker\Anaconda3\envs\attachment\lib\site-packages\flask\app.py", line 1936, in dispatch_request
    return self.view_functions[rule.endpoint](**req.view_args)
  File "C:\Users\chilker\Projects\RP_Trending\QCSTM_124\app\routes.py", line 172, in download_csv
    zipf.write('output/'+file)
  File "C:\Users\chilker\Anaconda3\envs\attachment\lib\zipfile.py", line 1727, in write
    zinfo = ZipInfo.from_file(filename, arcname,
  File "C:\Users\chilker\Anaconda3\envs\attachment\lib\zipfile.py", line 501, in from_file
    st = os.stat(filename)
FileNotFoundError: [WinError 3] The system cannot find the path specified: 'output/bsc_cdd,bsc_id,date_begin,date_end,e_dat_nc,e_dat_vii,final_dis,id,is_ie,lot_nc,lot_vii,operator_1,operator_2,pip_cdd,pip_id,timestamp\r\n05-2022,asdfasdfasdf,2021-09-01,2021-09-03,2021-09-28,2021-09-01,pass,39,True,qrstuvwxyz,032121345ADEVIUO,Leroy,,04-2022,rtwergfdg,2021-09-09 18:35:17.948727\r\n05-2024,asdfasdf,2021-09-01,2021-09-17,2021-09-08,2021-09-01,pass,40,True,sdfgsdfg,010222844AIUO,Percy,,05-2024,asdfafad,2021-09-09 18:40:22.445018\r\n03-2022,asdasfdf,2021-07-14,2021-09-25,2021-10-29,2021-09-05,fail,41,True,werdfgfd,022221248ADEVIUO,Nala,,04-2022,ewrsdfhgdg,2021-09-09 18:44:50.070412\r\n03-2022,asdasfdf,2021-07-14,2021-09-25,2021-10-29,2021-09-05,fail,42,True,werdfgfd,022221245ADEVIUO,Nala,,04-2022,ewrsdfhgdg,2021-09-09 18:46:28.248258\r\n04-2024,asdfadf,2021-09-01,2021-09-02,2021-09-30,2021-06-11,fail,43,True,akjhcvbgkj,102922176ADEVIUO,Penelope,,05-2024,324zdgf3,2021-09-09 19:05:54.021757\r\n03-2021,292929,2021-09-09,None,2021-09-17,2021-09-13,pass,44,True,Bite me,020321102ADEVIUO,Eddie Campione,,01-2021,lslsls,2021-09-09 19:20:47.793649\r\n03-2021,292929,2021-09-09,None,2021-09-17,2021-09-13,pass,45,True,Bite me,020321102ADEVIUO,Eddie Campione,,01-2021,lslsls,2021-09-13 16:52:16.299582\r\n01-2022,Luminex,2021-09-01,2021-09-01,2021-09-01,2021-09-01,pass,46,True,Luminex,010121463ADEVIUO,Luminex,,01-2022,Luminex,2021-09-13 16:59:31.941088\r\n01-2022,Luminex,2021-09-01,2021-09-01,2021-09-01,2021-09-01,pass,47,False,Luminex,010121374ADEVIUO,Luminex,,01-2022,Luminex,2021-09-13 17:02:41.567193\r\n'
2021-09-15 13:10:14,082 INFO: Attachment startup [in C:\Users\chilker\Projects\RP_Trending\QCSTM_124\app\__init__.py:29]
2021-09-15 13:10:23,962 ERROR: Exception on /download_csv [POST] [in C:\Users\chilker\Anaconda3\envs\attachment\lib\site-packages\flask\app.py:1891]
Traceback (most recent call last):
  File "C:\Users\chilker\Anaconda3\envs\attachment\lib\site-packages\flask\app.py", line 2447, in wsgi_app
    response = self.full_dispatch_request()
  File "C:\Users\chilker\Anaconda3\envs\attachment\lib\site-packages\flask\app.py", line 1952, in full_dispatch_request
    rv = self.handle_user_exception(e)
  File "C:\Users\chilker\Anaconda3\envs\attachment\lib\site-packages\flask\app.py", line 1821, in handle_user_exception
    reraise(exc_type, exc_value, tb)
  File "C:\Users\chilker\Anaconda3\envs\attachment\lib\site-packages\flask\_compat.py", line 39, in reraise
    raise value
  File "C:\Users\chilker\Anaconda3\envs\attachment\lib\site-packages\flask\app.py", line 1950, in full_dispatch_request
    rv = self.dispatch_request()
  File "C:\Users\chilker\Anaconda3\envs\attachment\lib\site-packages\flask\app.py", line 1936, in dispatch_request
    return self.view_functions[rule.endpoint](**req.view_args)
  File "C:\Users\chilker\Projects\RP_Trending\QCSTM_124\app\routes.py", line 122, in download_csv
    column_names = [col for col in query_2[0].__dict__]
IndexError: list index out of range
2021-09-15 13:10:40,585 INFO: Attachment startup [in C:\Users\chilker\Projects\RP_Trending\QCSTM_124\app\__init__.py:29]
2021-09-24 10:04:34,795 INFO: Attachment startup [in C:\Users\chilker\Projects\RP_Trending\QCSTM_124\app\__init__.py:29]
2021-09-24 10:05:18,814 ERROR: Exception on /download_csv [POST] [in C:\Users\chilker\Anaconda3\envs\attachment\lib\site-packages\flask\app.py:1891]
Traceback (most recent call last):
  File "C:\Users\chilker\Anaconda3\envs\attachment\lib\site-packages\flask\app.py", line 2447, in wsgi_app
    response = self.full_dispatch_request()
  File "C:\Users\chilker\Anaconda3\envs\attachment\lib\site-packages\flask\app.py", line 1952, in full_dispatch_request
    rv = self.handle_user_exception(e)
  File "C:\Users\chilker\Anaconda3\envs\attachment\lib\site-packages\flask\app.py", line 1821, in handle_user_exception
    reraise(exc_type, exc_value, tb)
  File "C:\Users\chilker\Anaconda3\envs\attachment\lib\site-packages\flask\_compat.py", line 39, in reraise
    raise value
  File "C:\Users\chilker\Anaconda3\envs\attachment\lib\site-packages\flask\app.py", line 1950, in full_dispatch_request
    rv = self.dispatch_request()
  File "C:\Users\chilker\Anaconda3\envs\attachment\lib\site-packages\flask\app.py", line 1936, in dispatch_request
    return self.view_functions[rule.endpoint](**req.view_args)
  File "C:\Users\chilker\Projects\RP_Trending\QCSTM_124\app\routes.py", line 122, in download_csv
    column_names = [col for col in query_2[0].__dict__]
IndexError: list index out of range
2021-09-24 10:05:54,471 ERROR: Exception on /download_csv [POST] [in C:\Users\chilker\Anaconda3\envs\attachment\lib\site-packages\flask\app.py:1891]
Traceback (most recent call last):
  File "C:\Users\chilker\Anaconda3\envs\attachment\lib\site-packages\flask\app.py", line 2447, in wsgi_app
    response = self.full_dispatch_request()
  File "C:\Users\chilker\Anaconda3\envs\attachment\lib\site-packages\flask\app.py", line 1952, in full_dispatch_request
    rv = self.handle_user_exception(e)
  File "C:\Users\chilker\Anaconda3\envs\attachment\lib\site-packages\flask\app.py", line 1821, in handle_user_exception
    reraise(exc_type, exc_value, tb)
  File "C:\Users\chilker\Anaconda3\envs\attachment\lib\site-packages\flask\_compat.py", line 39, in reraise
    raise value
  File "C:\Users\chilker\Anaconda3\envs\attachment\lib\site-packages\flask\app.py", line 1950, in full_dispatch_request
    rv = self.dispatch_request()
  File "C:\Users\chilker\Anaconda3\envs\attachment\lib\site-packages\flask\app.py", line 1936, in dispatch_request
    return self.view_functions[rule.endpoint](**req.view_args)
  File "C:\Users\chilker\Projects\RP_Trending\QCSTM_124\app\routes.py", line 122, in download_csv
    column_names = [col for col in query_2[0].__dict__]
IndexError: list index out of range
2021-09-24 10:06:47,882 ERROR: Exception on /download_csv [POST] [in C:\Users\chilker\Anaconda3\envs\attachment\lib\site-packages\flask\app.py:1891]
Traceback (most recent call last):
  File "C:\Users\chilker\Anaconda3\envs\attachment\lib\site-packages\flask\app.py", line 2447, in wsgi_app
    response = self.full_dispatch_request()
  File "C:\Users\chilker\Anaconda3\envs\attachment\lib\site-packages\flask\app.py", line 1952, in full_dispatch_request
    rv = self.handle_user_exception(e)
  File "C:\Users\chilker\Anaconda3\envs\attachment\lib\site-packages\flask\app.py", line 1821, in handle_user_exception
    reraise(exc_type, exc_value, tb)
  File "C:\Users\chilker\Anaconda3\envs\attachment\lib\site-packages\flask\_compat.py", line 39, in reraise
    raise value
  File "C:\Users\chilker\Anaconda3\envs\attachment\lib\site-packages\flask\app.py", line 1950, in full_dispatch_request
    rv = self.dispatch_request()
  File "C:\Users\chilker\Anaconda3\envs\attachment\lib\site-packages\flask\app.py", line 1936, in dispatch_request
    return self.view_functions[rule.endpoint](**req.view_args)
  File "C:\Users\chilker\Projects\RP_Trending\QCSTM_124\app\routes.py", line 122, in download_csv
    column_names = [col for col in query_2[0].__dict__]
IndexError: list index out of range
